Workbook

Sheet Overview
A1: ERP API — Tiến độ theo Module
A2: Mỗi sheet = 1 module · mỗi dòng = 1 feature. Số liệu tổng hợp bên dưới tham chiếu trực tiếp từ các sheet module.
A3: No | B3: Module | C3: Progress | D3: isDone
A4: 1 | B4: Auth | C4: =AVERAGE('Auth'!C4:C23) | D4: =IF(C4>=1,"Finished",IF(C4<=0,"Not started","In progress"))
A5: 2 | B5: Users | C5: =AVERAGE('Users'!C4:C22) | D5: =IF(C5>=1,"Finished",IF(C5<=0,"Not started","In progress"))
A6: 3 | B6: Roles | C6: =AVERAGE('Roles'!C4:C17) | D6: =IF(C6>=1,"Finished",IF(C6<=0,"Not started","In progress"))
A7: 4 | B7: Permissions | C7: =AVERAGE('Permissions'!C4:C15) | D7: =IF(C7>=1,"Finished",IF(C7<=0,"Not started","In progress"))
A8: 5 | B8: System Resources | C8: =AVERAGE('System Resources'!C4:C14) | D8: =IF(C8>=1,"Finished",IF(C8<=0,"Not started","In progress"))
A9: 6 | B9: Departments | C9: =AVERAGE('Departments'!C4:C11) | D9: =IF(C9>=1,"Finished",IF(C9<=0,"Not started","In progress"))
A10: 7 | B10: Employee Profiles | C10: =AVERAGE('Employee Profiles'!C4:C11) | D10: =IF(C10>=1,"Finished",IF(C10<=0,"Not started","In progress"))
A11: 8 | B11: Identity (CCCD) | C11: =AVERAGE('Identity (CCCD)'!C4:C8) | D11: =IF(C11>=1,"Finished",IF(C11<=0,"Not started","In progress"))
A12: 9 | B12: User Avatars | C12: =AVERAGE('User Avatars'!C4:C8) | D12: =IF(C12>=1,"Finished",IF(C12<=0,"Not started","In progress"))
A13: 10 | B13: Notifications | C13: =AVERAGE('Notifications'!C4:C26) | D13: =IF(C13>=1,"Finished",IF(C13<=0,"Not started","In progress"))
A14: 11 | B14: Audit Log | C14: =AVERAGE('Audit Log'!C4:C11) | D14: =IF(C14>=1,"Finished",IF(C14<=0,"Not started","In progress"))
A15: 12 | B15: Tickets | C15: =AVERAGE('Tickets'!C4:C16) | D15: =IF(C15>=1,"Finished",IF(C15<=0,"Not started","In progress"))
A16: 13 | B16: ATS - Recruitment Requests | C16: =AVERAGE('ATS - Recruitment Requests'!C4:C11) | D16: =IF(C16>=1,"Finished",IF(C16<=0,"Not started","In progress"))
A17: 14 | B17: ATS - Job Posts | C17: =AVERAGE('ATS - Job Posts'!C4:C16) | D17: =IF(C17>=1,"Finished",IF(C17<=0,"Not started","In progress"))
A18: 15 | B18: ATS - Candidates | C18: =AVERAGE('ATS - Candidates'!C4:C8) | D18: =IF(C18>=1,"Finished",IF(C18<=0,"Not started","In progress"))
A19: 16 | B19: ATS - Submissions | C19: =AVERAGE('ATS - Submissions'!C4:C17) | D19: =IF(C19>=1,"Finished",IF(C19<=0,"Not started","In progress"))
A20: 17 | B20: ATS - CV Screening (AI) | C20: =AVERAGE('ATS - CV Screening (AI)'!C4:C15) | D20: =IF(C20>=1,"Finished",IF(C20<=0,"Not started","In progress"))
A21: 18 | B21: ATS - Storage (S3) | C21: =AVERAGE('ATS - Storage (S3)'!C4:C13) | D21: =IF(C21>=1,"Finished",IF(C21<=0,"Not started","In progress"))
A22: 19 | B22: Publishing Automation | C22: =AVERAGE('Publishing Automation'!C4:C23) | D22: =IF(C22>=1,"Finished",IF(C22<=0,"Not started","In progress"))
A23: 20 | B23: Address | C23: =AVERAGE('Address'!C4:C9) | D23: =IF(C23>=1,"Finished",IF(C23<=0,"Not started","In progress"))
A24: 21 | B24: Cron & Scheduled Tasks | C24: =AVERAGE('Cron & Scheduled Tasks'!C4:C9) | D24: =IF(C24>=1,"Finished",IF(C24<=0,"Not started","In progress"))
A25: 22 | B25: Mail | C25: =AVERAGE('Mail'!C4:C8) | D25: =IF(C25>=1,"Finished",IF(C25<=0,"Not started","In progress"))
A26: 23 | B26: Core Infrastructure | C26: =AVERAGE('Core Infrastructure'!C4:C23) | D26: =IF(C26>=1,"Finished",IF(C26<=0,"Not started","In progress"))
A27: 24 | B27: Database & Deployment | C27: =AVERAGE('Database & Deployment'!C4:C12) | D27: =IF(C27>=1,"Finished",IF(C27<=0,"Not started","In progress"))
B29: Tổng tiến độ hệ thống | C29: =AVERAGE(C4:C27) | D29: =COUNTIF(D4:D27,"Finished")&"/"&COUNTA(D4:D27)&" modules"
B31: Quy ước: Progress = % hoàn thành của feature. isDone = Finished (100%) / In progress (1–99%) / Not started (0%).
B32: Đánh giá dựa trên mã nguồn tại commit 1925c1f (branch main), ngày 18/09/2026.
A34: Timeline triển khai theo giai đoạn
A35: Progress của hạng mục có module liên kết = trung bình Progress các module ở bảng trên (chữ xanh lá). Hạng mục chưa có module = ô nhập tay (chữ xanh dương). Dòng phòng ban / giai đoạn tự cộng dồn từ hạng mục con.
A36: No | B36: Hạng mục | C36: Bắt đầu | D36: Kết thúc | E36: Progress | F36: isDone | G36: Kế hoạch | H36: Lịch trình | I36: Module liên kết
A37: 0 | B37: Khởi tạo Nền tảng | C37: 46258 | D37: 46277 | E37: 1 | F37: =IF(E37>=1,"Finished",IF(E37<=0,"Not started","In progress")) | G37: =IF(OR(C37="",D37=""),"",MAX(0,MIN(1,(TODAY()-C37)/(D37-C37)))) | H37: =IF(E37>=1,"Hoàn thành",IF(OR(C37="",D37=""),"",IF(TODAY()<C37,"Chưa đến hạn",IF(TODAY()>D37,"Trễ hạn",IF(E37>=G37,"Đúng tiến độ","Chậm tiến độ"))))) | I37: Auth, Users, Roles, Permissions, System Resources, User Avatars, Notifications, Audit Log, Tickets, Mail, Cron & Scheduled Tasks, Address, Core Infrastructure, Database & Deployment
A38: I. | B38: Nền tảng Tổ chức | C38: 46279 | D38: 46319 | E38: =AVERAGE(E39) | F38: =IF(E38>=1,"Finished",IF(E38<=0,"Not started","In progress")) | G38: =IF(OR(C38="",D38=""),"",MAX(0,MIN(1,(TODAY()-C38)/(D38-C38)))) | H38: =IF(E38>=1,"Hoàn thành",IF(OR(C38="",D38=""),"",IF(TODAY()<C38,"Chưa đến hạn",IF(TODAY()>D38,"Trễ hạn",IF(E38>=G38,"Đúng tiến độ","Chậm tiến độ")))))
A39: 1 | B39: Phòng HCNS & QLNL | C39: 46279 | D39: 46340 | E39: =AVERAGE(E40,E41,E42) | F39: =IF(E39>=1,"Finished",IF(E39<=0,"Not started","In progress")) | G39: =IF(OR(C39="",D39=""),"",MAX(0,MIN(1,(TODAY()-C39)/(D39-C39)))) | H39: =IF(E39>=1,"Hoàn thành",IF(OR(C39="",D39=""),"",IF(TODAY()<C39,"Chưa đến hạn",IF(TODAY()>D39,"Trễ hạn",IF(E39>=G39,"Đúng tiến độ","Chậm tiến độ")))))
A40: 1.1 | B40: Quản lý thông tin người lao động Nghiệp vụ: Sơ đồ tổ chức số, hồ sơ nhân sự số, hợp đồng lao động, trạng thái người lao động, phân bổ phòng ban. | C40: 46279 | D40: 46291 | E40: =AVERAGE(C9,C10,C11) | F40: =IF(E40>=1,"Finished",IF(E40<=0,"Not started","In progress")) | G40: =IF(OR(C40="",D40=""),"",MAX(0,MIN(1,(TODAY()-C40)/(D40-C40)))) | H40: =IF(E40>=1,"Hoàn thành",IF(OR(C40="",D40=""),"",IF(TODAY()<C40,"Chưa đến hạn",IF(TODAY()>D40,"Trễ hạn",IF(E40>=G40,"Đúng tiến độ","Chậm tiến độ"))))) | I40: Departments, Employee Profiles, Identity (CCCD)
A41: 1.2 | B41: Quản lý thông tin ứng viên Nghiệp vụ: Tracking trạng thái ứng viên (CV -> Phỏng vấn -> Offer), lưu trữ hồ sơ, đánh giá phỏng vấn. | C41: 46293 | D41: 46305 | E41: =AVERAGE(C16,C17,C18,C19,C20,C21,C22) | F41: =IF(E41>=1,"Finished",IF(E41<=0,"Not started","In progress")) | G41: =IF(OR(C41="",D41=""),"",MAX(0,MIN(1,(TODAY()-C41)/(D41-C41)))) | H41: =IF(E41>=1,"Hoàn thành",IF(OR(C41="",D41=""),"",IF(TODAY()<C41,"Chưa đến hạn",IF(TODAY()>D41,"Trễ hạn",IF(E41>=G41,"Đúng tiến độ","Chậm tiến độ"))))) | I41: ATS - Recruitment Requests, ATS - Job Posts, ATS - Candidates, ATS - Submissions, ATS - CV Screening (AI), ATS - Storage (S3), Publishing Automation
A42: 1.3 | B42: Thống kê + Tính tiền công và lương Nghiệp vụ: Tích hợp API chấm công (GPS/Vân tay), quản lý đơn từ (nghỉ phép, OT), xuất bảng công và tự động tính lương theo công thức (chưa xuất dòng tiền - nhường phần đó cho GĐ 4). | C42: 46307 | D42: 46340 | E42: 0 | F42: =IF(E42>=1,"Finished",IF(E42<=0,"Not started","In progress")) | G42: =IF(OR(C42="",D42=""),"",MAX(0,MIN(1,(TODAY()-C42)/(D42-C42)))) | H42: =IF(E42>=1,"Hoàn thành",IF(OR(C42="",D42=""),"",IF(TODAY()<C42,"Chưa đến hạn",IF(TODAY()>D42,"Trễ hạn",IF(E42>=G42,"Đúng tiến độ","Chậm tiến độ")))))
A43: II. | B43: Chuỗi Cung ứng & Thực địa | C43: 46342 | D43: 46592 | E43: =AVERAGE(E44,E48,E52,E56) | F43: =IF(E43>=1,"Finished",IF(E43<=0,"Not started","In progress")) | G43: =IF(OR(C43="",D43=""),"",MAX(0,MIN(1,(TODAY()-C43)/(D43-C43)))) | H43: =IF(E43>=1,"Hoàn thành",IF(OR(C43="",D43=""),"",IF(TODAY()<C43,"Chưa đến hạn",IF(TODAY()>D43,"Trễ hạn",IF(E43>=G43,"Đúng tiến độ","Chậm tiến độ")))))
...

Sheet Auth
A1: Auth
A2: Nguồn: src/auth
A3: No | B3: Feature Name | C3: Progress | D3: isDone
A4: 1 | B4: Đăng ký tài khoản (email + mật khẩu) | C4: 1 | D4: =IF(C4>=1,"Finished",IF(C4<=0,"Not started","In progress"))
A5: 2 | B5: Đăng nhập cấp JWT access + refresh token | C5: 1 | D5: =IF(C5>=1,"Finished",IF(C5<=0,"Not started","In progress"))
A6: 3 | B6: Đăng nhập Google OAuth | C6: 1 | D6: =IF(C6>=1,"Finished",IF(C6<=0,"Not started","In progress"))
A7: 4 | B7: Làm mới access token (refresh) | C7: 1 | D7: =IF(C7>=1,"Finished",IF(C7<=0,"Not started","In progress"))
A8: 5 | B8: Đăng xuất phiên hiện tại | C8: 1 | D8: =IF(C8>=1,"Finished",IF(C8<=0,"Not started","In progress"))
A9: 6 | B9: Lấy hồ sơ người dùng hiện tại (/auth/me) | C9: 1 | D9: =IF(C9>=1,"Finished",IF(C9<=0,"Not started","In progress"))
A10: 7 | B10: Quên mật khẩu - gửi OTP qua email | C10: 1 | D10: =IF(C10>=1,"Finished",IF(C10<=0,"Not started","In progress"))
A11: 8 | B11: Quên mật khẩu - gửi OTP qua Zalo ZNS | C11: 0.6 | D11: =IF(C11>=1,"Finished",IF(C11<=0,"Not started","In progress"))
A12: 9 | B12: Đặt lại mật khẩu bằng OTP | C12: 1 | D12: =IF(C12>=1,"Finished",IF(C12<=0,"Not started","In progress"))
A13: 10 | B13: Đổi mật khẩu (đã đăng nhập) | C13: 1 | D13: =IF(C13>=1,"Finished",IF(C13<=0,"Not started","In progress"))
A14: 11 | B14: Xác thực email bằng link token | C14: 1 | D14: =IF(C14>=1,"Finished",IF(C14<=0,"Not started","In progress"))
A15: 12 | B15: Gửi OTP xác thực tài khoản | C15: 0.8 | D15: =IF(C15>=1,"Finished",IF(C15<=0,"Not started","In progress"))
... A23: 20 | B23: Admin - xác minh email hộ user | C23: 1 | D23: =IF(C23>=1,"Finished",IF(C23<=0,"Not started","In progress"))
A24: Không tính vào Progress — Unit test & Tối ưu hoá tương lai
A25: 21 | B25: Unit test (auth.service + auth.controller) | C25: 1 | D25: =IF(C25>=1,"Finished",IF(C25<=0,"Not started","In progress"))
A26: 22 | B26: Tối ưu Index CSDL: Tránh Sequential Scan để giảm triệt để Disk I/O | D26: In progress
A27: 23 | B27: Tối ưu câu lệnh truy vấn: Triệt tiêu lỗi N+1 Query bằng JOIN hoặc batching | D27: In progress
A28: 24 | B28: Tối ưu Payload RESTful: Chỉ truy vấn các trường cần thiết, tránh payload chứa tất cả thông tin | D28: In progress
B30: Tổng kết module (chỉ tính các feature phía trên) | C30: =AVERAGE(C4:C23) | D30: =COUNTIF(D4:D23,"Finished")&"/"&COUNTA(D4:D23)&" finished"
B32: Cách dùng: chỉ sửa cột C (Progress, 0%–100%). Cột D tự tính.
B33: Ô tô vàng = chưa hoàn thiện; di chuột vào tên feature để xem ghi chú kỹ thuật.
B34: Unit test và hạng mục tối ưu (nền xám) nằm ngoài vùng tổng kết, không ảnh hưởng Progress.

Sheet Users
A1: Users
A2: Nguồn: src/users
A3: No | B3: Feature Name | C3: Progress | D3: isDone
A4: 1 | B4: Tạo người dùng | C4: 1 | D4: =IF(C4>=1,"Finished",IF(C4<=0,"Not started","In progress"))
A5: 2 | B5: Danh sách người dùng (phân trang, lọc) | C5: 1 | D5: =IF(C5>=1,"Finished",IF(C5<=0,"Not started","In progress"))
A6: 3 | B6: Xem chi tiết người dùng | C6: 1 | D6: =IF(C6>=1,"Finished",IF(C6<=0,"Not started","In progress"))
A7: 4 | B7: Cập nhật người dùng | C7: 1 | D7: =IF(C7>=1,"Finished",IF(C7<=0,"Not started","In progress"))
A8: 5 | B8: Xoá mềm người dùng | C8: 1 | D8: =IF(C8>=1,"Finished",IF(C8<=0,"Not started","In progress"))
A9: 6 | B9: Thùng rác (recycle bin) | C9: 1 | D9: =IF(C9>=1,"Finished",IF(C9<=0,"Not started","In progress"))
A10: 7 | B10: Khôi phục người dùng đã xoá | C10: 1 | D10: =IF(C10>=1,"Finished",IF(C10<=0,"Not started","In progress"))
A11: 8 | B11: Danh sách rút gọn (available) cho dropdown | C11: 1 | D11: =IF(C11>=1,"Finished",IF(C11<=0,"Not started","In progress"))
A12: 9 | B12: Xem hồ sơ nhanh (quick profile) | C12: 1 | D12: =IF(C12>=1,"Finished",IF(C12<=0,"Not started","In progress"))
A13: 10 | B13: Xem hồ sơ đầy đủ (full profile) | C13: 1 | D13: =IF(C13>=1,"Finished",IF(C13<=0,"Not started","In progress"))
A14: 11 | B14: Ma trận quyền truy cập toàn bộ user | C14: 1 | D14: =IF(C14>=1,"Finished",IF(C14<=0,"Not started","In progress"))
A15: 12 | B15: Chi tiết quyền truy cập của một user | C15: 1 | D15: =IF(C15>=1,"Finished",IF(C15<=0,"Not started","In progress"))
... A22: 19 | B22: Từ chối claim hồ sơ | C22: 1 | D22: =IF(C22>=1,"Finished",IF(C22<=0,"Not started","In progress"))
A23: Không tính vào Progress — Unit test & Tối ưu hoá tương lai
A24: 20 | B24: Unit test (users.service + users.controller) | C24: 1 | D24: =IF(C24>=1,"Finished",IF(C24<=0,"Not started","In progress"))
A25: 21 | B25: Tối ưu Index CSDL: Tránh Sequential Scan để giảm triệt để Disk I/O | D25: In progress
A26: 22 | B26: Tối ưu câu lệnh truy vấn: Triệt tiêu lỗi N+1 Query bằng JOIN hoặc batching | D26: In progress
A27: 23 | B27: Tối ưu Payload RESTful: Chỉ truy vấn các trường cần thiết, tránh payload chứa tất cả thông tin | D27: In progress
B29: Tổng kết module (chỉ tính các feature phía trên) | C29: =AVERAGE(C4:C22) | D29: =COUNTIF(D4:D22,"Finished")&"/"&COUNTA(D4:D22)&" finished"
B31: Cách dùng: chỉ sửa cột C (Progress, 0%–100%). Cột D tự tính.
B32: Ô tô vàng = chưa hoàn thiện; di chuột vào tên feature để xem ghi chú kỹ thuật.
B33: Unit test và hạng mục tối ưu (nền xám) nằm ngoài vùng tổng kết, không ảnh hưởng Progress.

Sheet Roles
A1: Roles
A2: Nguồn: src/roles
A3: No | B3: Feature Name | C3: Progress | D3: isDone
A4: 1 | B4: Tạo vai trò | C4: 1 | D4: =IF(C4>=1,"Finished",IF(C4<=0,"Not started","In progress"))
A5: 2 | B5: Danh sách vai trò | C5: 1 | D5: =IF(C5>=1,"Finished",IF(C5<=0,"Not started","In progress"))
A6: 3 | B6: Chi tiết vai trò kèm quyền | C6: 1 | D6: =IF(C6>=1,"Finished",IF(C6<=0,"Not started","In progress"))
A7: 4 | B7: Cập nhật vai trò | C7: 1 | D7: =IF(C7>=1,"Finished",IF(C7<=0,"Not started","In progress"))
A8: 5 | B8: Xoá mềm vai trò | C8: 1 | D8: =IF(C8>=1,"Finished",IF(C8<=0,"Not started","In progress"))
A9: 6 | B9: Thùng rác vai trò | C9: 1 | D9: =IF(C9>=1,"Finished",IF(C9<=0,"Not started","In progress"))
A10: 7 | B10: Khôi phục vai trò | C10: 1 | D10: =IF(C10>=1,"Finished",IF(C10<=0,"Not started","In progress"))
A11: 8 | B11: Bật/tắt trạng thái vai trò | C11: 1 | D11: =IF(C11>=1,"Finished",IF(C11<=0,"Not started","In progress"))
A12: 9 | B12: Danh sách rút gọn (available) | C12: 1 | D12: =IF(C12>=1,"Finished",IF(C12<=0,"Not started","In progress"))
A13: 10 | B13: Danh mục quyền theo nhóm (grouped permissions) | C13: 1 | D13: =IF(C13>=1,"Finished",IF(C13<=0,"Not started","In progress"))
A14: 11 | B14: Cập nhật hàng loạt quyền của vai trò | C14: 1 | D14: =IF(C14>=1,"Finished",IF(C14<=0,"Not started","In progress"))
A15: 12 | B15: Gán hàng loạt người dùng vào vai trò | C15: 1 | D15: =IF(C15>=1,"Finished",IF(C15<=0,"Not started","In progress"))
... A17: 14 | B17: Gỡ một người dùng khỏi vai trò | C17: 1 | D17: =IF(C17>=1,"Finished",IF(C17<=0,"Not started","In progress"))
A18: Không tính vào Progress — Unit test & Tối ưu hoá tương lai
A19: 15 | B19: Unit test (roles.service + roles.controller) | C19: 1 | D19: =IF(C19>=1,"Finished",IF(C19<=0,"Not started","In progress"))
A20: 16 | B20: Tối ưu Index CSDL: Tránh Sequential Scan để giảm triệt để Disk I/O | D20: In progress
A21: 17 | B21: Tối ưu câu lệnh truy vấn: Triệt tiêu lỗi N+1 Query bằng JOIN hoặc batching | D21: In progress
A22: 18 | B22: Tối ưu Payload RESTful: Chỉ truy vấn các trường cần thiết, tránh payload chứa tất cả thông tin | D22: In progress
B24: Tổng kết module (chỉ tính các feature phía trên) | C24: =AVERAGE(C4:C17) | D24: =COUNTIF(D4:D17,"Finished")&"/"&COUNTA(D4:D17)&" finished"
B26: Cách dùng: chỉ sửa cột C (Progress, 0%–100%). Cột D tự tính.
B27: Ô tô vàng = chưa hoàn thiện; di chuột vào tên feature để xem ghi chú kỹ thuật.
B28: Unit test và hạng mục tối ưu (nền xám) nằm ngoài vùng tổng kết, không ảnh hưởng Progress.

Sheet Permissions
A1: Permissions
A2: Nguồn: src/permissions
A3: No | B3: Feature Name | C3: Progress | D3: isDone
A4: 1 | B4: Tạo quyền | C4: 1 | D4: =IF(C4>=1,"Finished",IF(C4<=0,"Not started","In progress"))
A5: 2 | B5: Danh sách quyền | C5: 1 | D5: =IF(C5>=1,"Finished",IF(C5<=0,"Not started","In progress"))
A6: 3 | B6: Chi tiết quyền | C6: 1 | D6: =IF(C6>=1,"Finished",IF(C6<=0,"Not started","In progress"))
A7: 4 | B7: Cập nhật quyền | C7: 1 | D7: =IF(C7>=1,"Finished",IF(C7<=0,"Not started","In progress"))
A8: 5 | B8: Xoá quyền | C8: 1 | D8: =IF(C8>=1,"Finished",IF(C8<=0,"Not started","In progress"))
A9: 6 | B9: Danh sách rút gọn (available) | C9: 1 | D9: =IF(C9>=1,"Finished",IF(C9<=0,"Not started","In progress"))
A10: 7 | B10: Danh mục enum quyền | C10: 1 | D10: =IF(C10>=1,"Finished",IF(C10<=0,"Not started","In progress"))
A11: 8 | B11: Bật/tắt trạng thái quyền | C11: 1 | D11: =IF(C11>=1,"Finished",IF(C11<=0,"Not started","In progress"))
A12: 9 | B12: Khôi phục quyền | C12: 1 | D12: =IF(C12>=1,"Finished",IF(C12<=0,"Not started","In progress"))
A13: 10 | B13: Guard bắt buộc đủ quyền (@RequirePermissions) | C13: 1 | D13: =IF(C13>=1,"Finished",IF(C13<=0,"Not started","In progress"))
A14: 11 | B14: Guard bắt buộc một trong các quyền (@RequireAnyPermissions) | C14: 1 | D14: =IF(C14>=1,"Finished",IF(C14<=0,"Not started","In progress"))
A15: 12 | B15: Cache Redis cho tra cứu quyền | C15: 1 | D15: =IF(C15>=1,"Finished",IF(C15<=0,"Not started","In progress"))
A16: Không tính vào Progress — Unit test & Tối ưu hoá tương lai
A17: 13 | B17: Unit test (permissions.service + controller) | C17: 1 | D17: =IF(C17>=1,"Finished",IF(C17<=0,"Not started","In progress"))
A18: 14 | B18: Tối ưu Index CSDL: Tránh Sequential Scan để giảm triệt để Disk I/O | D18: In progress
A19: 15 | B19: Tối ưu câu lệnh truy vấn: Triệt tiêu lỗi N+1 Query bằng JOIN hoặc batching | D19: In progress
A20: 16 | B20: Tối ưu Payload RESTful: Chỉ truy vấn các trường cần thiết, tránh payload chứa tất cả thông tin | D20: In progress
B22: Tổng kết module (chỉ tính các feature phía trên) | C22: =AVERAGE(C4:C15) | D22: =COUNTIF(D4:D15,"Finished")&"/"&COUNTA(D4:D15)&" finished"
B24: Cách dùng: chỉ sửa cột C (Progress, 0%–100%). Cột D tự tính.
B25: Ô tô vàng = chưa hoàn thiện; di chuột vào tên feature để xem ghi chú kỹ thuật.
B26: Unit test và hạng mục tối ưu (nền xám) nằm ngoài vùng tổng kết, không ảnh hưởng Progress.

Sheet System Resources
A1: System Resources
A2: Nguồn: src/resources
A3: No | B3: Feature Name | C3: Progress | D3: isDone
A4: 1 | B4: Tạo tài nguyên hệ thống | C4: 1 | D4: =IF(C4>=1,"Finished",IF(C4<=0,"Not started","In progress"))
A5: 2 | B5: Danh sách tài nguyên | C5: 1 | D5: =IF(C5>=1,"Finished",IF(C5<=0,"Not started","In progress"))
A6: 3 | B6: Chi tiết tài nguyên | C6: 1 | D6: =IF(C6>=1,"Finished",IF(C6<=0,"Not started","In progress"))
A7: 4 | B7: Cập nhật tài nguyên | C7: 1 | D7: =IF(C7>=1,"Finished",IF(C7<=0,"Not started","In progress"))
A8: 5 | B8: Xoá mềm tài nguyên | C8: 1 | D8: =IF(C8>=1,"Finished",IF(C8<=0,"Not started","In progress"))
A9: 6 | B9: Danh sách rút gọn (available) | C9: 1 | D9: =IF(C9>=1,"Finished",IF(C9<=0,"Not started","In progress"))
A10: 7 | B10: Ma trận phân quyền (resource x action) | C10: 1 | D10: =IF(C10>=1,"Finished",IF(C10<=0,"Not started","In progress"))
A11: 8 | B11: Thùng rác tài nguyên | C11: 1 | D11: =IF(C11>=1,"Finished",IF(C11<=0,"Not started","In progress"))
A12: 9 | B12: Bật/tắt trạng thái tài nguyên | C12: 1 | D12: =IF(C12>=1,"Finished",IF(C12<=0,"Not started","In progress"))
A13: 10 | B13: Khôi phục tài nguyên | C13: 1 | D13: =IF(C13>=1,"Finished",IF(C13<=0,"Not started","In progress"))
A14: 11 | B14: Cron dọn thùng rác (02:00 hằng ngày) | C14: 1 | D14: =IF(C14>=1,"Finished",IF(C14<=0,"Not started","In progress"))
A15: Không tính vào Progress — Unit test & Tối ưu hoá tương lai
A16: 12 | B16: Unit test (system-resources.service + controller) | C16: 1 | D16: =IF(C16>=1,"Finished",IF(C16<=0,"Not started","In progress"))
A17: 13 | B17: Tối ưu Index CSDL: Tránh Sequential Scan để giảm triệt để Disk I/O | D17: In progress
A18: 14 | B18: Tối ưu câu lệnh truy vấn: Triệt tiêu lỗi N+1 Query bằng JOIN hoặc batching | D18: In progress
A19: 15 | B19: Tối ưu Payload RESTful: Chỉ truy vấn các trường cần thiết, tránh payload chứa tất cả thông tin | D19: In progress
B21: Tổng kết module (chỉ tính các feature phía trên) | C21: =AVERAGE(C4:C14) | D21: =COUNTIF(D4:D14,"Finished")&"/"&COUNTA(D4:D14)&" finished"
B23: Cách dùng: chỉ sửa cột C (Progress, 0%–100%). Cột D tự tính.
B24: Ô tô vàng = chưa hoàn thiện; di chuột vào tên feature để xem ghi chú kỹ thuật.
B25: Unit test và hạng mục tối ưu (nền xám) nằm ngoài vùng tổng kết, không ảnh hưởng Progress.

Sheet Departments
A1: Departments
A2: Nguồn: src/departments
A3: No | B3: Feature Name | C3: Progress | D3: isDone
A4: 1 | B4: Tạo phòng ban | C4: 1 | D4: =IF(C4>=1,"Finished",IF(C4<=0,"Not started","In progress"))
A5: 2 | B5: Danh sách phòng ban (lọc, phân trang) | C5: 1 | D5: =IF(C5>=1,"Finished",IF(C5<=0,"Not started","In progress"))
A6: 3 | B6: Tra cứu theo id hoặc slug | C6: 1 | D6: =IF(C6>=1,"Finished",IF(C6<=0,"Not started","In progress"))
A7: 4 | B7: Cây phân cấp phòng ban (tree) | C7: 1 | D7: =IF(C7>=1,"Finished",IF(C7<=0,"Not started","In progress"))
A8: 5 | B8: Cập nhật phòng ban | C8: 1 | D8: =IF(C8>=1,"Finished",IF(C8<=0,"Not started","In progress"))
A9: 6 | B9: Gán trưởng phòng ban | C9: 1 | D9: =IF(C9>=1,"Finished",IF(C9<=0,"Not started","In progress"))
A10: 7 | B10: Xoá mềm phòng ban | C10: 1 | D10: =IF(C10>=1,"Finished",IF(C10<=0,"Not started","In progress"))
A11: 8 | B11: Sinh slug tự động | C11: 1 | D11: =IF(C11>=1,"Finished",IF(C11<=0,"Not started","In progress"))
A12: Không tính vào Progress — Unit test & Tối ưu hoá tương lai
A13: 9 | B13: Unit test | C13: 0 | D13: =IF(C13>=1,"Finished",IF(C13<=0,"Not started","In progress"))
A14: 10 | B14: Tối ưu Index CSDL: Tránh Sequential Scan để giảm triệt để Disk I/O | D14: In progress
A15: 11 | B15: Tối ưu câu lệnh truy vấn: Triệt tiêu lỗi N+1 Query bằng JOIN hoặc batching | D15: In progress
A16: 12 | B16: Tối ưu Payload RESTful: Chỉ truy vấn các trường cần thiết, tránh payload chứa tất cả thông tin | D16: In progress
B18: Tổng kết module (chỉ tính các feature phía trên) | C18: =AVERAGE(C4:C11) | D18: =COUNTIF(D4:D11,"Finished")&"/"&COUNTA(D4:D11)&" finished"
B20: Cách dùng: chỉ sửa cột C (Progress, 0%–100%). Cột D tự tính.
B21: Ô tô vàng = chưa hoàn thiện; di chuột vào tên feature để xem ghi chú kỹ thuật.
B22: Unit test và hạng mục tối ưu (nền xám) nằm ngoài vùng tổng kết, không ảnh hưởng Progress.

Sheet Employee Profiles
A1: Employee Profiles
A2: Nguồn: src/employee-profiles
A3: No | B3: Feature Name | C3: Progress | D3: isDone
A4: 1 | B4: Danh sách hồ sơ nhân viên (lọc) | C4: 1 | D4: =IF(C4>=1,"Finished",IF(C4<=0,"Not started","In progress"))
A5: 2 | B5: Tra cứu hồ sơ theo mã nhân viên | C5: 1 | D5: =IF(C5>=1,"Finished",IF(C5<=0,"Not started","In progress"))
A6: 3 | B6: Cập nhật hồ sơ nhân viên | C6: 1 | D6: =IF(C6>=1,"Finished",IF(C6<=0,"Not started","In progress"))
A7: 4 | B7: Truy xuất hồ sơ có bảo vệ (xác thực lại) | C7: 1 | D7: =IF(C7>=1,"Finished",IF(C7<=0,"Not started","In progress"))
A8: 5 | B8: Liên kết hồ sơ với tài khoản qua luồng claim | C8: 1 | D8: =IF(C8>=1,"Finished",IF(C8<=0,"Not started","In progress"))
A9: 6 | B9: Phân bổ phòng ban / vai trò cho nhân viên | C9: 1 | D9: =IF(C9>=1,"Finished",IF(C9<=0,"Not started","In progress"))
A10: 7 | B10: Trạng thái người lao động (thử việc / chính thức / nghỉ việc) | C10: 0.3 | D10: =IF(C10>=1,"Finished",IF(C10<=0,"Not started","In progress"))
A11: 8 | B11: Quản lý hợp đồng lao động | C11: 0 | D11: =IF(C11>=1,"Finished",IF(C11<=0,"Not started","In progress"))
A12: Không tính vào Progress — Unit test & Tối ưu hoá tương lai
A13: 9 | B13: Unit test | C13: 0 | D13: =IF(C13>=1,"Finished",IF(C13<=0,"Not started","In progress"))
A14: 10 | B14: Tối ưu Index CSDL: Tránh Sequential Scan để giảm triệt để Disk I/O | D14: In progress
A15: 11 | B15: Tối ưu câu lệnh truy vấn: Triệt tiêu lỗi N+1 Query bằng JOIN hoặc batching | D15: In progress
A16: 12 | B16: Tối ưu Payload RESTful: Chỉ truy vấn các trường cần thiết, tránh payload chứa tất cả thông tin | D16: In progress
B18: Tổng kết module (chỉ tính các feature phía trên) | C18: =AVERAGE(C4:C11) | D18: =COUNTIF(D4:D11,"Finished")&"/"&COUNTA(D4:D11)&" finished"
B20: Cách dùng: chỉ sửa cột C (Progress, 0%–100%). Cột D tự tính.
B21: Ô tô vàng = chưa hoàn thiện; di chuột vào tên feature để xem ghi chú kỹ thuật.
B22: Unit test và hạng mục tối ưu (nền xám) nằm ngoài vùng tổng kết, không ảnh hưởng Progress.

Sheet Identity (CCCD)
A1: Identity (CCCD)
A2: Nguồn: src/identity
A3: No | B3: Feature Name | C3: Progress | D3: isDone
A4: 1 | B4: Tạo bản ghi CCCD cho người dùng | C4: 1 | D4: =IF(C4>=1,"Finished",IF(C4<=0,"Not started","In progress"))
A5: 2 | B5: Cập nhật bản ghi CCCD | C5: 1 | D5: =IF(C5>=1,"Finished",IF(C5<=0,"Not started","In progress"))
A6: 3 | B6: Truy xuất CCCD có bảo vệ (xác thực lại) | C6: 1 | D6: =IF(C6>=1,"Finished",IF(C6<=0,"Not started","In progress"))
A7: 4 | B7: Phân tích mã QR CCCD | C7: 1 | D7: =IF(C7>=1,"Finished",IF(C7<=0,"Not started","In progress"))
A8: 5 | B8: Mã hoá dữ liệu định danh ở mức trường | C8: 1 | D8: =IF(C8>=1,"Finished",IF(C8<=0,"Not started","In progress"))
A9: Không tính vào Progress — Unit test & Tối ưu hoá tương lai
A10: 6 | B10: Unit test | C10: 0 | D10: =IF(C10>=1,"Finished",IF(C10<=0,"Not started","In progress"))
A11: 7 | B11: Tối ưu Index CSDL: Tránh Sequential Scan để giảm triệt để Disk I/O | D11: In progress
A12: 8 | B12: Tối ưu câu lệnh truy vấn: Triệt tiêu lỗi N+1 Query bằng JOIN hoặc batching | D12: In progress
A13: 9 | B13: Tối ưu Payload RESTful: Chỉ truy vấn các trường cần thiết, tránh payload chứa tất cả thông tin | D13: In progress
B15: Tổng kết module (chỉ tính các feature phía trên) | C15: =AVERAGE(C4:C8) | D15: =COUNTIF(D4:D8,"Finished")&"/"&COUNTA(D4:D8)&" finished"
B17: Cách dùng: chỉ sửa cột C (Progress, 0%–100%). Cột D tự tính.
B18: Ô tô vàng = chưa hoàn thiện; di chuột vào tên feature để xem ghi chú kỹ thuật.
B19: Unit test và hạng mục tối ưu (nền xám) nằm ngoài vùng tổng kết, không ảnh hưởng Progress.

Sheet User Avatars
A1: User Avatars
A2: Nguồn: src/user-avatars
A3: No | B3: Feature Name | C3: Progress | D3: isDone
A4: 1 | B4: Cập nhật / thay ảnh đại diện | C4: 1 | D4: =IF(C4>=1,"Finished",IF(C4<=0,"Not started","In progress"))
A5: 2 | B5: Lưu lịch sử ảnh đại diện (isCurrent) | C5: 1 | D5: =IF(C5>=1,"Finished",IF(C5<=0,"Not started","In progress"))
A6: 3 | B6: Giới hạn tối đa 5 ảnh, tự xoá ảnh cũ | C6: 1 | D6: =IF(C6>=1,"Finished",IF(C6<=0,"Not started","In progress"))
A7: 4 | B7: Xoá cache user liên quan khi đổi ảnh | C7: 1 | D7: =IF(C7>=1,"Finished",IF(C7<=0,"Not started","In progress"))
A8: 5 | B8: Upload file ảnh trực tiếp lên storage | C8: 0 | D8: =IF(C8>=1,"Finished",IF(C8<=0,"Not started","In progress"))
A9: Không tính vào Progress — Unit test & Tối ưu hoá tương lai
A10: 6 | B10: Unit test | C10: 0 | D10: =IF(C10>=1,"Finished",IF(C10<=0,"Not started","In progress"))
B12: Tổng kết module (chỉ tính các feature phía trên) | C12: =AVERAGE(C4:C8) | D12: =COUNTIF(D4:D8,"Finished")&"/"&COUNTA(D4:D8)&" finished"
B14: Cách dùng: chỉ sửa cột C (Progress, 0%–100%). Cột D tự tính.
B15: Ô tô vàng = chưa hoàn thiện; di chuột vào tên feature để xem ghi chú kỹ thuật.
B16: Unit test và hạng mục tối ưu (nền xám) nằm ngoài vùng tổng kết, không ảnh hưởng Progress.

Sheet Notifications
A1: Notifications
A2: Nguồn: src/notifications
A3: No | B3: Feature Name | C3: Progress | D3: isDone
A4: 1 | B4: Lấy thông báo của tôi | C4: 1 | D4: =IF(C4>=1,"Finished",IF(C4<=0,"Not started","In progress"))
A5: 2 | B5: Feed thông báo phân trang | C5: 1 | D5: =IF(C5>=1,"Finished",IF(C5<=0,"Not started","In progress"))
A6: 3 | B6: Danh sách thông báo có lọc | C6: 1 | D6: =IF(C6>=1,"Finished",IF(C6<=0,"Not started","In progress"))
A7: 4 | B7: Danh mục enum thông báo | C7: 1 | D7: =IF(C7>=1,"Finished",IF(C7<=0,"Not started","In progress"))
A8: 5 | B8: Đánh dấu đã đọc một thông báo | C8: 1 | D8: =IF(C8>=1,"Finished",IF(C8<=0,"Not started","In progress"))
A9: 6 | B9: Đánh dấu đã đọc tất cả | C9: 1 | D9: =IF(C9>=1,"Finished",IF(C9<=0,"Not started","In progress"))
A10: 7 | B10: WebSocket gateway xác thực bằng JWT | C10: 1 | D10: =IF(C10>=1,"Finished",IF(C10<=0,"Not started","In progress"))
A11: 8 | B11: Đẩy realtime tới room của user | C11: 1 | D11: =IF(C11>=1,"Finished",IF(C11<=0,"Not started","In progress"))
A12: 9 | B12: Phát sự kiện hệ thống tới user | C12: 1 | D12: =IF(C12>=1,"Finished",IF(C12<=0,"Not started","In progress"))
A13: 10 | B13: Sự kiện: người dùng đăng ký | C13: 1 | D13: =IF(C13>=1,"Finished",IF(C13<=0,"Not started","In progress"))
A14: 11 | B14: Sự kiện: gửi/duyệt/từ chối claim hồ sơ | C14: 1 | D14: =IF(C14>=1,"Finished",IF(C14<=0,"Not started","In progress"))
A15: 12 | B15: Sự kiện: yêu cầu tuyển dụng mới | C15: 1 | D15: =IF(C15>=1,"Finished",IF(C15<=0,"Not started","In progress"))
... A26: 23 | B26: Seed dữ liệu thông báo mẫu (dev/test) | C26: 1 | D26: =IF(C26>=1,"Finished",IF(C26<=0,"Not started","In progress"))
A27: Không tính vào Progress — Unit test & Tối ưu hoá tương lai
A28: 24 | B28: Unit test | C28: 0 | D28: =IF(C28>=1,"Finished",IF(C28<=0,"Not started","In progress"))
A29: 25 | B29: Tối ưu Index CSDL: Tránh Sequential Scan để giảm triệt để Disk I/O | D29: In progress
A30: 26 | B30: Tối ưu câu lệnh truy vấn: Triệt tiêu lỗi N+1 Query bằng JOIN hoặc batching | D30: In progress
A31: 27 | B31: Tối ưu Payload RESTful: Chỉ truy vấn các trường cần thiết, tránh payload chứa tất cả thông tin | D31: In progress
B33: Tổng kết module (chỉ tính các feature phía trên) | C33: =AVERAGE(C4:C26) | D33: =COUNTIF(D4:D26,"Finished")&"/"&COUNTA(D4:D26)&" finished"
B35: Cách dùng: chỉ sửa cột C (Progress, 0%–100%). Cột D tự tính.
B36: Ô tô vàng = chưa hoàn thiện; di chuột vào tên feature để xem ghi chú kỹ thuật.
B37: Unit test và hạng mục tối ưu (nền xám) nằm ngoài vùng tổng kết, không ảnh hưởng Progress.

Sheet Audit Log
A1: Audit Log
A2: Nguồn: src/audit-log
A3: No | B3: Feature Name | C3: Progress | D3: isDone
A4: 1 | B4: Ghi nhật ký hành động (logAction) | C4: 1 | D4: =IF(C4>=1,"Finished",IF(C4<=0,"Not started","In progress"))
A5: 2 | B5: Truy vấn nhật ký có lọc + phân trang | C5: 1 | D5: =IF(C5>=1,"Finished",IF(C5<=0,"Not started","In progress"))
A6: 3 | B6: Phân vùng hiển thị theo phạm vi (global / phòng ban) | C6: 1 | D6: =IF(C6>=1,"Finished",IF(C6<=0,"Not started","In progress"))
A7: 4 | B7: Endpoint ghi log từ phía client | C7: 1 | D7: =IF(C7>=1,"Finished",IF(C7<=0,"Not started","In progress"))
A8: 5 | B8: Seed dữ liệu nhật ký mẫu | C8: 1 | D8: =IF(C8>=1,"Finished",IF(C8<=0,"Not started","In progress"))
A9: 6 | B9: Entity cơ sở Auditable (created/updated/deleted by) | C9: 1 | D9: =IF(C9>=1,"Finished",IF(C9<=0,"Not started","In progress"))
A10: 7 | B10: Job xuất nhật ký (audit export) | C10: 0.15 | D10: =IF(C10>=1,"Finished",IF(C10<=0,"Not started","In progress"))
A11: 8 | B11: Chính sách lưu trữ / xoá nhật ký (retention) | C11: 0.15 | D11: =IF(C11>=1,"Finished",IF(C11<=0,"Not started","In progress"))
A12: Không tính vào Progress — Unit test & Tối ưu hoá tương lai
A13: 9 | B13: Unit test | C13: 0 | D13: =IF(C13>=1,"Finished",IF(C13<=0,"Not started","In progress"))
A14: 10 | B14: Tối ưu Index CSDL: Tránh Sequential Scan để giảm triệt để Disk I/O | D14: In progress
A15: 11 | B15: Tối ưu câu lệnh truy vấn: Triệt tiêu lỗi N+1 Query bằng JOIN hoặc batching | D15: In progress
A16: 12 | B16: Tối ưu Payload RESTful: Chỉ truy vấn các trường cần thiết, tránh payload chứa tất cả thông tin | D16: In progress
B18: Tổng kết module (chỉ tính các feature phía trên) | C18: =AVERAGE(C4:C11) | D18: =COUNTIF(D4:D11,"Finished")&"/"&COUNTA(D4:D11)&" finished"
B20: Cách dùng: chỉ sửa cột C (Progress, 0%–100%). Cột D tự tính.
B21: Ô tô vàng = chưa hoàn thiện; di chuột vào tên feature để xem ghi chú kỹ thuật.
B22: Unit test và hạng mục tối ưu (nền xám) nằm ngoài vùng tổng kết, không ảnh hưởng Progress.

Sheet Tickets
A1: Tickets
A2: Nguồn: src/tickets
A3: No | B3: Feature Name | C3: Progress | D3: isDone
A4: 1 | B4: Tạo phiếu yêu cầu (tự sinh ticket code) | C4: 1 | D4: =IF(C4>=1,"Finished",IF(C4<=0,"Not started","In progress"))
A5: 2 | B5: Danh sách / lọc phiếu yêu cầu | C5: 1 | D5: =IF(C5>=1,"Finished",IF(C5<=0,"Not started","In progress"))
A6: 3 | B6: Chi tiết phiếu yêu cầu | C6: 1 | D6: =IF(C6>=1,"Finished",IF(C6<=0,"Not started","In progress"))
A7: 4 | B7: Giao phiếu cho người xử lý | C7: 1 | D7: =IF(C7>=1,"Finished",IF(C7<=0,"Not started","In progress"))
A8: 5 | B8: Đặt lịch họp cho phiếu | C8: 1 | D8: =IF(C8>=1,"Finished",IF(C8<=0,"Not started","In progress"))
A9: 6 | B9: Ghi nhận kết quả cuộc họp | C9: 1 | D9: =IF(C9>=1,"Finished",IF(C9<=0,"Not started","In progress"))
A10: 7 | B10: Giải quyết phiếu (resolve) | C10: 1 | D10: =IF(C10>=1,"Finished",IF(C10<=0,"Not started","In progress"))
A11: 8 | B11: Từ chối phiếu (reject) | C11: 1 | D11: =IF(C11>=1,"Finished",IF(C11<=0,"Not started","In progress"))
A12: 9 | B12: Đóng phiếu (close) | C12: 1 | D12: =IF(C12>=1,"Finished",IF(C12<=0,"Not started","In progress"))
A13: 10 | B13: Mở lại phiếu (reopen) | C13: 1 | D13: =IF(C13>=1,"Finished",IF(C13<=0,"Not started","In progress"))
A14: 11 | B14: Tính hạn phản hồi / hạn xử lý theo SLA | C14: 1 | D14: =IF(C14>=1,"Finished",IF(C14<=0,"Not started","In progress"))
A15: 12 | B15: Scheduler quét vi phạm SLA | C15: 1 | D15: =IF(C15>=1,"Finished",IF(C15<=0,"Not started","In progress"))
A16: 13 | B16: Thông báo cảnh báo vi phạm SLA | C16: 1 | D16: =IF(C16>=1,"Finished",IF(C16<=0,"Not started","In progress"))
A17: Không tính vào Progress — Unit test & Tối ưu hoá tương lai
A18: 14 | B18: Unit test | C18: 0 | D18: =IF(C18>=1,"Finished",IF(C18<=0,"Not started","In progress"))
A19: 15 | B19: Tối ưu Index CSDL: Tránh Sequential Scan để giảm triệt để Disk I/O | D19: In progress
A20: 16 | B20: Tối ưu câu lệnh truy vấn: Triệt tiêu lỗi N+1 Query bằng JOIN hoặc batching | D20: In progress
A21: 17 | B21: Tối ưu Payload RESTful: Chỉ truy vấn các trường cần thiết, tránh payload chứa tất cả thông tin | D21: In progress
B23: Tổng kết module (chỉ tính các feature phía trên) | C23: =AVERAGE(C4:C16) | D23: =COUNTIF(D4:D16,"Finished")&"/"&COUNTA(D4:D16)&" finished"
B25: Cách dùng: chỉ sửa cột C (Progress, 0%–100%). Cột D tự tính.
B26: Ô tô vàng = chưa hoàn thiện; di chuột vào tên feature để xem ghi chú kỹ thuật.
B27: Unit test và hạng mục tối ưu (nền xám) nằm ngoài vùng tổng kết, không ảnh hưởng Progress.

Sheet ATS - Recruitment Requests
A1: ATS - Recruitment Requests
A2: Nguồn: src/ats
A3: No | B3: Feature Name | C3: Progress | D3: isDone
A4: 1 | B4: Tạo yêu cầu tuyển dụng | C4: 1 | D4: =IF(C4>=1,"Finished",IF(C4<=0,"Not started","In progress"))
A5: 2 | B5: Danh sách theo phạm vi RBAC | C5: 1 | D5: =IF(C5>=1,"Finished",IF(C5<=0,"Not started","In progress"))
A6: 3 | B6: Chi tiết yêu cầu tuyển dụng | C6: 1 | D6: =IF(C6>=1,"Finished",IF(C6<=0,"Not started","In progress"))
A7: 4 | B7: Cập nhật yêu cầu | C7: 1 | D7: =IF(C7>=1,"Finished",IF(C7<=0,"Not started","In progress"))
A8: 5 | B8: Duyệt / từ chối yêu cầu | C8: 1 | D8: =IF(C8>=1,"Finished",IF(C8<=0,"Not started","In progress"))
A9: 6 | B9: Huỷ yêu cầu | C9: 1 | D9: =IF(C9>=1,"Finished",IF(C9<=0,"Not started","In progress"))
A10: 7 | B10: Kiểm soát chuyển trạng thái (transitionStatus) | C10: 1 | D10: =IF(C10>=1,"Finished",IF(C10<=0,"Not started","In progress"))
A11: 8 | B11: Phát sự kiện recruitment.request.created | C11: 1 | D11: =IF(C11>=1,"Finished",IF(C11<=0,"Not started","In progress"))
A12: Không tính vào Progress — Unit test & Tối ưu hoá tương lai
A13: 9 | B13: Unit test | C13: 0 | D13: =IF(C13>=1,"Finished",IF(C13<=0,"Not started","In progress"))
A14: 10 | B14: Tối ưu Index CSDL: Tránh Sequential Scan để giảm triệt để Disk I/O | D14: In progress
A15: 11 | B15: Tối ưu câu lệnh truy vấn: Triệt tiêu lỗi N+1 Query bằng JOIN hoặc batching | D15: In progress
A16: 12 | B16: Tối ưu Payload RESTful: Chỉ truy vấn các trường cần thiết, tránh payload chứa tất cả thông tin | D16: In progress
B18: Tổng kết module (chỉ tính các feature phía trên) | C18: =AVERAGE(C4:C11) | D18: =COUNTIF(D4:D11,"Finished")&"/"&COUNTA(D4:D11)&" finished"
B20: Cách dùng: chỉ sửa cột C (Progress, 0%–100%). Cột D tự tính.
B21: Ô tô vàng = chưa hoàn thiện; di chuột vào tên feature để xem ghi chú kỹ thuật.
B22: Unit test và hạng mục tối ưu (nền xám) nằm ngoài vùng tổng kết, không ảnh hưởng Progress.

Sheet ATS - Job Posts
A1: ATS - Job Posts
A2: Nguồn: src/ats
A3: No | B3: Feature Name | C3: Progress | D3: isDone
A4: 1 | B4: AI gợi ý JD từ ghi chú thô | C4: 1 | D4: =IF(C4>=1,"Finished",IF(C4<=0,"Not started","In progress"))
A5: 2 | B5: Thư viện JD mẫu (templates) | C5: 1 | D5: =IF(C5>=1,"Finished",IF(C5<=0,"Not started","In progress"))
A6: 3 | B6: Tạo bản nháp JD | C6: 1 | D6: =IF(C6>=1,"Finished",IF(C6<=0,"Not started","In progress"))
A7: 4 | B7: Danh sách tin tuyển dụng theo RBAC | C7: 1 | D7: =IF(C7>=1,"Finished",IF(C7<=0,"Not started","In progress"))
A8: 5 | B8: Chi tiết tin theo id hoặc mã | C8: 1 | D8: =IF(C8>=1,"Finished",IF(C8<=0,"Not started","In progress"))
A9: 6 | B9: Cập nhật tin tuyển dụng | C9: 1 | D9: =IF(C9>=1,"Finished",IF(C9<=0,"Not started","In progress"))
A10: 7 | B10: Gửi duyệt trưởng bộ phận | C10: 1 | D10: =IF(C10>=1,"Finished",IF(C10<=0,"Not started","In progress"))
A11: 8 | B11: Trưởng bộ phận duyệt / từ chối | C11: 1 | D11: =IF(C11>=1,"Finished",IF(C11<=0,"Not started","In progress"))
A12: 9 | B12: Đăng tin (publish) | C12: 1 | D12: =IF(C12>=1,"Finished",IF(C12<=0,"Not started","In progress"))
A13: 10 | B13: Đóng tin (close) | C13: 1 | D13: =IF(C13>=1,"Finished",IF(C13<=0,"Not started","In progress"))
A14: 11 | B14: Phân phối tin lên nền tảng ngoài khi publish | C14: 0.35 | D14: =IF(C14>=1,"Finished",IF(C14<=0,"Not started","In progress"))
A15: 12 | B15: Thu hồi tin trên nền tảng ngoài khi đóng | C15: 0.3 | D15: =IF(C15>=1,"Finished",IF(C15<=0,"Not started","In progress"))
A16: 13 | B16: Phát sự kiện job_post.approval_requested / published | C16: 1 | D16: =IF(C16>=1,"Finished",IF(C16<=0,"Not started","In progress"))
A17: Không tính vào Progress — Unit test & Tối ưu hoá tương lai
A18: 14 | B18: Unit test | C18: 0 | D18: =IF(C18>=1,"Finished",IF(C18<=0,"Not started","In progress"))
A19: 15 | B19: Tối ưu Index CSDL: Tránh Sequential Scan để giảm triệt để Disk I/O | D19: In progress
A20: 16 | B20: Tối ưu câu lệnh truy vấn: Triệt tiêu lỗi N+1 Query bằng JOIN hoặc batching | D20: In progress
A21: 17 | B21: Tối ưu Payload RESTful: Chỉ truy vấn các trường cần thiết, tránh payload chứa tất cả thông tin | D21: In progress
B23: Tổng kết module (chỉ tính các feature phía trên) | C23: =AVERAGE(C4:C16) | D23: =COUNTIF(D4:D16,"Finished")&"/"&COUNTA(D4:D16)&" finished"
B25: Cách dùng: chỉ sửa cột C (Progress, 0%–100%). Cột D tự tính.
B26: Ô tô vàng = chưa hoàn thiện; di chuột vào tên feature để xem ghi chú kỹ thuật.
B27: Unit test và hạng mục tối ưu (nền xám) nằm ngoài vùng tổng kết, không ảnh hưởng Progress.

Sheet ATS - Candidates
A1: ATS - Candidates
A2: Nguồn: src/ats
A3: No | B3: Feature Name | C3: Progress | D3: isDone
A4: 1 | B4: Danh sách hồ sơ ứng viên theo RBAC | C4: 1 | D4: =IF(C4>=1,"Finished",IF(C4<=0,"Not started","In progress"))
A5: 2 | B5: Chi tiết hồ sơ ứng viên | C5: 1 | D5: =IF(C5>=1,"Finished",IF(C5<=0,"Not started","In progress"))
A6: 3 | B6: Tìm hoặc tạo hồ sơ ứng viên | C6: 1 | D6: =IF(C6>=1,"Finished",IF(C6<=0,"Not started","In progress"))
A7: 4 | B7: Tìm hoặc tạo hồ sơ trong transaction (EntityManager) | C7: 1 | D7: =IF(C7>=1,"Finished",IF(C7<=0,"Not started","In progress"))
A8: 5 | B8: Khử trùng lặp ứng viên theo email / số điện thoại | C8: 1 | D8: =IF(C8>=1,"Finished",IF(C8<=0,"Not started","In progress"))
A9: Không tính vào Progress — Unit test & Tối ưu hoá tương lai
A10: 6 | B10: Unit test | C10: 0 | D10: =IF(C10>=1,"Finished",IF(C10<=0,"Not started","In progress"))
A11: 7 | B11: Tối ưu Index CSDL: Tránh Sequential Scan để giảm triệt để Disk I/O | D11: In progress
A12: 8 | B12: Tối ưu câu lệnh truy vấn: Triệt tiêu lỗi N+1 Query bằng JOIN hoặc batching | D12: In progress
A13: 9 | B13: Tối ưu Payload RESTful: Chỉ truy vấn các trường cần thiết, tránh payload chứa tất cả thông tin | D13: In progress
B15: Tổng kết module (chỉ tính các feature phía trên) | C15: =AVERAGE(C4:C8) | D15: =COUNTIF(D4:D8,"Finished")&"/"&COUNTA(D4:D8)&" finished"
B17: Cách dùng: chỉ sửa cột C (Progress, 0%–100%). Cột D tự tính.
B18: Ô tô vàng = chưa hoàn thiện; di chuột vào tên feature để xem ghi chú kỹ thuật.
B19: Unit test và hạng mục tối ưu (nền xám) nằm ngoài vùng tổng kết, không ảnh hưởng Progress.

Sheet ATS - Submissions
A1: ATS - Submissions
A2: Nguồn: src/ats
A3: No | B3: Feature Name | C3: Progress | D3: isDone
A4: 1 | B4: Nộp hồ sơ từ portal công khai | C4: 1 | D4: =IF(C4>=1,"Finished",IF(C4<=0,"Not started","In progress"))
A5: 2 | B5: Tiếp nhận webhook từ nền tảng tuyển dụng | C5: 1 | D5: =IF(C5>=1,"Finished",IF(C5<=0,"Not started","In progress"))
A6: 3 | B6: Nộp hồ sơ thủ công kèm file CV | C6: 1 | D6: =IF(C6>=1,"Finished",IF(C6<=0,"Not started","In progress"))
A7: 4 | B7: Upload và nạp hồ sơ trực tiếp | C7: 1 | D7: =IF(C7>=1,"Finished",IF(C7<=0,"Not started","In progress"))
A8: 5 | B8: Tạo bản ghi ApplicationSubmission | C8: 1 | D8: =IF(C8>=1,"Finished",IF(C8<=0,"Not started","In progress"))
A9: 6 | B9: Tìm hoặc tạo JobApplication | C9: 1 | D9: =IF(C9>=1,"Finished",IF(C9<=0,"Not started","In progress"))
A10: 7 | B10: Bảng pipeline ứng tuyển theo tin tuyển dụng | C10: 1 | D10: =IF(C10>=1,"Finished",IF(C10<=0,"Not started","In progress"))
A11: 8 | B11: Chuyển giai đoạn ứng tuyển (update phase) | C11: 1 | D11: =IF(C11>=1,"Finished",IF(C11<=0,"Not started","In progress"))
A12: 9 | B12: Danh sách submission của một đơn ứng tuyển | C12: 1 | D12: =IF(C12>=1,"Finished",IF(C12<=0,"Not started","In progress"))
A13: 10 | B13: Đưa ứng viên từ talent pool vào tin mới | C13: 1 | D13: =IF(C13>=1,"Finished",IF(C13<=0,"Not started","In progress"))
A14: 11 | B14: Xoá CV ngay lập tức (purge theo yêu cầu) | C14: 1 | D14: =IF(C14>=1,"Finished",IF(C14<=0,"Not started","In progress"))
A15: 12 | B15: Processor BullMQ xử lý upload CV | C15: 1 | D15: =IF(C15>=1,"Finished",IF(C15<=0,"Not started","In progress"))
... A17: 14 | B17: Lịch phỏng vấn & phiếu đánh giá phỏng vấn | C17: 0 | D17: =IF(C17>=1,"Finished",IF(C17<=0,"Not started","In progress"))
A18: Không tính vào Progress — Unit test & Tối ưu hoá tương lai
A19: 15 | B19: Unit test | C19: 0 | D19: =IF(C19>=1,"Finished",IF(C19<=0,"Not started","In progress"))
A20: 16 | B20: Tối ưu Index CSDL: Tránh Sequential Scan để giảm triệt để Disk I/O | D20: In progress
A21: 17 | B21: Tối ưu câu lệnh truy vấn: Triệt tiêu lỗi N+1 Query bằng JOIN hoặc batching | D21: In progress
A22: 18 | B22: Tối ưu Payload RESTful: Chỉ truy vấn các trường cần thiết, tránh payload chứa tất cả thông tin | D22: In progress
B24: Tổng kết module (chỉ tính các feature phía trên) | C24: =AVERAGE(C4:C17) | D24: =COUNTIF(D4:D17,"Finished")&"/"&COUNTA(D4:D17)&" finished"
B26: Cách dùng: chỉ sửa cột C (Progress, 0%–100%). Cột D tự tính.
B27: Ô tô vàng = chưa hoàn thiện; di chuột vào tên feature để xem ghi chú kỹ thuật.
B28: Unit test và hạng mục tối ưu (nền xám) nằm ngoài vùng tổng kết, không ảnh hưởng Progress.

Sheet ATS - CV Screening (AI)
A1: ATS - CV Screening (AI)
A2: Nguồn: src/ats
A3: No | B3: Feature Name | C3: Progress | D3: isDone
A4: 1 | B4: Trích xuất text từ CV dạng PDF | C4: 1 | D4: =IF(C4>=1,"Finished",IF(C4<=0,"Not started","In progress"))
A5: 2 | B5: Trích xuất text từ CV dạng DOCX | C5: 1 | D5: =IF(C5>=1,"Finished",IF(C5<=0,"Not started","In progress"))
A6: 3 | B6: AI sinh nội dung JD từ prompt | C6: 1 | D6: =IF(C6>=1,"Finished",IF(C6<=0,"Not started","In progress"))
A7: 4 | B7: AI trích xuất từ khoá / thông tin ứng viên từ CV | C7: 1 | D7: =IF(C7>=1,"Finished",IF(C7<=0,"Not started","In progress"))
A8: 5 | B8: AI chấm điểm CV so với JD | C8: 1 | D8: =IF(C8>=1,"Finished",IF(C8<=0,"Not started","In progress"))
A9: 6 | B9: Ghi nhận kết quả đánh giá (commitScreeningEvaluation) | C9: 1 | D9: =IF(C9>=1,"Finished",IF(C9<=0,"Not started","In progress"))
A10: 7 | B10: Áp kết quả sàng lọc vào pipeline | C10: 1 | D10: =IF(C10>=1,"Finished",IF(C10<=0,"Not started","In progress"))
A11: 8 | B11: Chấm lại / thử lại sàng lọc (rescreen) | C11: 1 | D11: =IF(C11>=1,"Finished",IF(C11<=0,"Not started","In progress"))
A12: 9 | B12: Consumer hàng đợi BullMQ cho sàng lọc CV | C12: 1 | D12: =IF(C12>=1,"Finished",IF(C12<=0,"Not started","In progress"))
A13: 10 | B13: Listener sự kiện ats.cv_submitted | C13: 1 | D13: =IF(C13>=1,"Finished",IF(C13<=0,"Not started","In progress"))
A14: 11 | B14: Kích hoạt thông báo khi ứng viên đạt điểm cao | C14: 1 | D14: =IF(C14>=1,"Finished",IF(C14<=0,"Not started","In progress"))
A15: 12 | B15: Hỗ trợ đa nhà cung cấp AI (Anthropic / Google GenAI) | C15: 1 | D15: =IF(C15>=1,"Finished",IF(C15<=0,"Not started","In progress"))
A16: Không tính vào Progress — Unit test & Tối ưu hoá tương lai
A17: 13 | B17: Unit test | C17: 0 | D17: =IF(C17>=1,"Finished",IF(C17<=0,"Not started","In progress"))
B19: Tổng kết module (chỉ tính các feature phía trên) | C19: =AVERAGE(C4:C15) | D19: =COUNTIF(D4:D15,"Finished")&"/"&COUNTA(D4:D15)&" finished"
B21: Cách dùng: chỉ sửa cột C (Progress, 0%–100%). Cột D tự tính.
B22: Ô tô vàng = chưa hoàn thiện; di chuột vào tên feature để xem ghi chú kỹ thuật.
B23: Unit test và hạng mục tối ưu (nền xám) nằm ngoài vùng tổng kết, không ảnh hưởng Progress.

Sheet ATS - Storage (S3)
A1: ATS - Storage (S3)
A2: Nguồn: src/ats
A3: No | B3: Feature Name | C3: Progress | D3: isDone
A4: 1 | B4: Cấu hình S3 client | C4: 1 | D4: =IF(C4>=1,"Finished",IF(C4<=0,"Not started","In progress"))
A5: 2 | B5: Upload CV theo stream lên S3 | C5: 1 | D5: =IF(C5>=1,"Finished",IF(C5<=0,"Not started","In progress"))
A6: 3 | B6: Lấy buffer file từ S3 | C6: 1 | D6: =IF(C6>=1,"Finished",IF(C6<=0,"Not started","In progress"))
A7: 4 | B7: Kiểm tra file tồn tại | C7: 1 | D7: =IF(C7>=1,"Finished",IF(C7<=0,"Not started","In progress"))
A8: 5 | B8: Sinh URL truy cập file | C8: 1 | D8: =IF(C8>=1,"Finished",IF(C8<=0,"Not started","In progress"))
A9: 6 | B9: Trích fileKey từ URL | C9: 1 | D9: =IF(C9>=1,"Finished",IF(C9<=0,"Not started","In progress"))
A10: 7 | B10: Lưu tạm cục bộ và thử upload lại | C10: 1 | D10: =IF(C10>=1,"Finished",IF(C10<=0,"Not started","In progress"))
A11: 8 | B11: Xoá file khỏi S3 | C11: 1 | D11: =IF(C11>=1,"Finished",IF(C11<=0,"Not started","In progress"))
A12: 9 | B12: Cron xoá CV hết hạn lưu trữ (03:00 hằng ngày) | C12: 1 | D12: =IF(C12>=1,"Finished",IF(C12<=0,"Not started","In progress"))
A13: 10 | B13: Cron thử lại upload đang chờ (mỗi 15 phút) | C13: 1 | D13: =IF(C13>=1,"Finished",IF(C13<=0,"Not started","In progress"))
A14: Không tính vào Progress — Unit test & Tối ưu hoá tương lai
A15: 11 | B15: Unit test | C15: 0 | D15: =IF(C15>=1,"Finished",IF(C15<=0,"Not started","In progress"))
B17: Tổng kết module (chỉ tính các feature phía trên) | C17: =AVERAGE(C4:C13) | D17: =COUNTIF(D4:D13,"Finished")&"/"&COUNTA(D4:D13)&" finished"
B19: Cách dùng: chỉ sửa cột C (Progress, 0%–100%). Cột D tự tính.
B20: Ô tô vàng = chưa hoàn thiện; di chuột vào tên feature để xem ghi chú kỹ thuật.
B21: Unit test và hạng mục tối ưu (nền xám) nằm ngoài vùng tổng kết, không ảnh hưởng Progress.

Sheet Publishing Automation
A1: Publishing Automation
A2: Nguồn: src/publishing-automation
A3: No | B3: Feature Name | C3: Progress | D3: isDone
A4: 1 | B4: Đăng ký tài khoản Facebook | C4: 1 | D4: =IF(C4>=1,"Finished",IF(C4<=0,"Not started","In progress"))
A5: 2 | B5: Danh sách tài khoản Facebook | C5: 1 | D5: =IF(C5>=1,"Finished",IF(C5<=0,"Not started","In progress"))
A6: 3 | B6: Cập nhật trạng thái tài khoản | C6: 1 | D6: =IF(C6>=1,"Finished",IF(C6<=0,"Not started","In progress"))
A7: 4 | B7: Đăng ký nhóm Facebook được quản lý | C7: 1 | D7: =IF(C7>=1,"Finished",IF(C7<=0,"Not started","In progress"))
A8: 5 | B8: Nhập hàng loạt nhóm (bulk import) | C8: 1 | D8: =IF(C8>=1,"Finished",IF(C8<=0,"Not started","In progress"))
A9: 6 | B9: Danh sách nhóm | C9: 1 | D9: =IF(C9>=1,"Finished",IF(C9<=0,"Not started","In progress"))
A10: 7 | B10: Gợi ý nhóm phù hợp theo tin tuyển dụng | C10: 1 | D10: =IF(C10>=1,"Finished",IF(C10<=0,"Not started","In progress"))
A11: 8 | B11: Cập nhật trạng thái tham gia nhóm | C11: 1 | D11: =IF(C11>=1,"Finished",IF(C11<=0,"Not started","In progress"))
A12: 9 | B12: Phân bổ lịch đăng giãn cách (staggered schedule) | C12: 1 | D12: =IF(C12>=1,"Finished",IF(C12<=0,"Not started","In progress"))
A13: 10 | B13: Tạo job tự động đăng tin | C13: 1 | D13: =IF(C13>=1,"Finished",IF(C13<=0,"Not started","In progress"))
A14: 11 | B14: Danh sách job theo tin ATS | C14: 1 | D14: =IF(C14>=1,"Finished",IF(C14<=0,"Not started","In progress"))
A15: 12 | B15: Chi tiết job tự động | C15: 1 | D15: =IF(C15>=1,"Finished",IF(C15<=0,"Not started","In progress"))
... A23: 20 | B23: Listener thông báo kết quả job | C23: 1 | D23: =IF(C23>=1,"Finished",IF(C23<=0,"Not started","In progress"))
A24: Không tính vào Progress — Unit test & Tối ưu hoá tương lai
A25: 21 | B25: Unit test | C25: 0 | D25: =IF(C25>=1,"Finished",IF(C25<=0,"Not started","In progress"))
A26: 22 | B26: Tối ưu Index CSDL: Tránh Sequential Scan để giảm triệt để Disk I/O | D26: In progress
A27: 23 | B27: Tối ưu câu lệnh truy vấn: Triệt tiêu lỗi N+1 Query bằng JOIN hoặc batching | D27: In progress
A28: 24 | B28: Tối ưu Payload RESTful: Chỉ truy vấn các trường cần thiết, tránh payload chứa tất cả thông tin | D28: In progress
B30: Tổng kết module (chỉ tính các feature phía trên) | C30: =AVERAGE(C4:C23) | D30: =COUNTIF(D4:D23,"Finished")&"/"&COUNTA(D4:D23)&" finished"
B32: Cách dùng: chỉ sửa cột C (Progress, 0%–100%). Cột D tự tính.
B33: Ô tô vàng = chưa hoàn thiện; di chuột vào tên feature để xem ghi chú kỹ thuật.
B34: Unit test và hạng mục tối ưu (nền xám) nằm ngoài vùng tổng kết, không ảnh hưởng Progress.

Sheet Address
A1: Address
A2: Nguồn: src/address
A3: No | B3: Feature Name | C3: Progress | D3: isDone
A4: 1 | B4: Phân tích & gợi ý địa chỉ từ text tự do | C4: 1 | D4: =IF(C4>=1,"Finished",IF(C4<=0,"Not started","In progress"))
A5: 2 | B5: Chuyển đổi địa chỉ cũ sang cấu trúc hành chính mới | C5: 1 | D5: =IF(C5>=1,"Finished",IF(C5<=0,"Not started","In progress"))
A6: 3 | B6: Danh sách tỉnh / thành phố | C6: 1 | D6: =IF(C6>=1,"Finished",IF(C6<=0,"Not started","In progress"))
A7: 4 | B7: Danh sách phường / xã theo mã tỉnh | C7: 1 | D7: =IF(C7>=1,"Finished",IF(C7<=0,"Not started","In progress"))
A8: 5 | B8: Cache Redis cho tra cứu địa giới | C8: 1 | D8: =IF(C8>=1,"Finished",IF(C8<=0,"Not started","In progress"))
A9: 6 | B9: Đăng ký AddressModule vào AppModule | C9: 0 | D9: =IF(C9>=1,"Finished",IF(C9<=0,"Not started","In progress"))
A10: Không tính vào Progress — Unit test & Tối ưu hoá tương lai
A11: 7 | B11: Unit test (address.service + address.controller) | C11: 1 | D11: =IF(C11>=1,"Finished",IF(C11<=0,"Not started","In progress"))
B13: Tổng kết module (chỉ tính các feature phía trên) | C13: =AVERAGE(C4:C9) | D13: =COUNTIF(D4:D9,"Finished")&"/"&COUNTA(D4:D9)&" finished"
B15: Cách dùng: chỉ sửa cột C (Progress, 0%–100%). Cột D tự tính.
B16: Ô tô vàng = chưa hoàn thiện; di chuột vào tên feature để xem ghi chú kỹ thuật.
B17: Unit test và hạng mục tối ưu (nền xám) nằm ngoài vùng tổng kết, không ảnh hưởng Progress.

Sheet Cron & Scheduled Tasks
A1: Cron & Scheduled Tasks
A2: Nguồn: src/cron + src/tasks
A3: No | B3: Feature Name | C3: Progress | D3: isDone
A4: 1 | B4: Cron dọn thùng rác toàn hệ thống (02:00) | C4: 1 | D4: =IF(C4>=1,"Finished",IF(C4<=0,"Not started","In progress"))
A5: 2 | B5: Cron xoá tài khoản chưa xác thực (00:00) | C5: 1 | D5: =IF(C5>=1,"Finished",IF(C5<=0,"Not started","In progress"))
A6: 3 | B6: API xem trạng thái các cron job | C6: 1 | D6: =IF(C6>=1,"Finished",IF(C6<=0,"Not started","In progress"))
A7: 4 | B7: API bật / tắt cron job | C7: 1 | D7: =IF(C7>=1,"Finished",IF(C7<=0,"Not started","In progress"))
A8: 5 | B8: API kích hoạt cron job thủ công | C8: 1 | D8: =IF(C8>=1,"Finished",IF(C8<=0,"Not started","In progress"))
A9: 6 | B9: Đăng ký TasksModule vào AppModule | C9: 0 | D9: =IF(C9>=1,"Finished",IF(C9<=0,"Not started","In progress"))
A10: Không tính vào Progress — Unit test & Tối ưu hoá tương lai
A11: 7 | B11: Unit test | C11: 0 | D11: =IF(C11>=1,"Finished",IF(C11<=0,"Not started","In progress"))
B13: Tổng kết module (chỉ tính các feature phía trên) | C13: =AVERAGE(C4:C9) | D13: =COUNTIF(D4:D9,"Finished")&"/"&COUNTA(D4:D9)&" finished"
B15: Cách dùng: chỉ sửa cột C (Progress, 0%–100%). Cột D tự tính.
B16: Ô tô vàng = chưa hoàn thiện; di chuột vào tên feature để xem ghi chú kỹ thuật.
B17: Unit test và hạng mục tối ưu (nền xám) nằm ngoài vùng tổng kết, không ảnh hưởng Progress.

Sheet Mail
A1: Mail
A2: Nguồn: src/mail + src/common/services
A3: No | B3: Feature Name | C3: Progress | D3: isDone
A4: 1 | B4: Cấu hình transport Nodemailer / MailerModule | C4: 1 | D4: =IF(C4>=1,"Finished",IF(C4<=0,"Not started","In progress"))
A5: 2 | B5: Gửi email chứa link xác thực | C5: 1 | D5: =IF(C5>=1,"Finished",IF(C5<=0,"Not started","In progress"))
A6: 3 | B6: Gửi email chứa mã OTP | C6: 1 | D6: =IF(C6>=1,"Finished",IF(C6<=0,"Not started","In progress"))
A7: 4 | B7: Hợp nhất 2 MailService trùng chức năng | C7: 0 | D7: =IF(C7>=1,"Finished",IF(C7<=0,"Not started","In progress"))
A8: 5 | B8: Template email tách riêng (view engine) | C8: 0 | D8: =IF(C8>=1,"Finished",IF(C8<=0,"Not started","In progress"))
A9: Không tính vào Progress — Unit test & Tối ưu hoá tương lai
A10: 6 | B10: Unit test | C10: 0 | D10: =IF(C10>=1,"Finished",IF(C10<=0,"Not started","In progress"))
B12: Tổng kết module (chỉ tính các feature phía trên) | C12: =AVERAGE(C4:C8) | D12: =COUNTIF(D4:D8,"Finished")&"/"&COUNTA(D4:D8)&" finished"
B14: Cách dùng: chỉ sửa cột C (Progress, 0%–100%). Cột D tự tính.
B15: Ô tô vàng = chưa hoàn thiện; di chuột vào tên feature để xem ghi chú kỹ thuật.
B16: Unit test và hạng mục tối ưu (nền xám) nằm ngoài vùng tổng kết, không ảnh hưởng Progress.

Sheet Core Infrastructure
A1: Core Infrastructure
A2: Nguồn: src/common + src/interceptors + src/config
A3: No | B3: Feature Name | C3: Progress | D3: isDone
A4: 1 | B4: Global exception filter chuẩn hoá lỗi | C4: 1 | D4: =IF(C4>=1,"Finished",IF(C4<=0,"Not started","In progress"))
A5: 2 | B5: Transform interceptor chuẩn hoá response | C5: 1 | D5: =IF(C5>=1,"Finished",IF(C5<=0,"Not started","In progress"))
A6: 3 | B6: JWT auth guard | C6: 1 | D6: =IF(C6>=1,"Finished",IF(C6<=0,"Not started","In progress"))
A7: 4 | B7: Permissions guard (RBAC) | C7: 1 | D7: =IF(C7>=1,"Finished",IF(C7<=0,"Not started","In progress"))
A8: 5 | B8: Rate limit toàn cục lưu trên Redis | C8: 1 | D8: =IF(C8>=1,"Finished",IF(C8<=0,"Not started","In progress"))
A9: 6 | B9: Throttler exception filter | C9: 1 | D9: =IF(C9>=1,"Finished",IF(C9<=0,"Not started","In progress"))
A10: 7 | B10: Cache service trên Redis (get/set/del/pattern) | C10: 1 | D10: =IF(C10>=1,"Finished",IF(C10<=0,"Not started","In progress"))
A11: 8 | B11: Decorator @Cacheable | C11: 1 | D11: =IF(C11>=1,"Finished",IF(C11<=0,"Not started","In progress"))
A12: 9 | B12: Decorator @CacheClear | C12: 1 | D12: =IF(C12>=1,"Finished",IF(C12<=0,"Not started","In progress"))
A13: 10 | B13: API xoá cache theo pattern (admin) | C13: 1 | D13: =IF(C13>=1,"Finished",IF(C13<=0,"Not started","In progress"))
A14: 11 | B14: Validate biến môi trường khi khởi động | C14: 1 | D14: =IF(C14>=1,"Finished",IF(C14<=0,"Not started","In progress"))
A15: 12 | B15: Health check endpoint (kiểm tra DB) | C15: 1 | D15: =IF(C15>=1,"Finished",IF(C15<=0,"Not started","In progress"))
... A23: 20 | B23: Tài liệu API Swagger / OpenAPI | C23: 0 | D23: =IF(C23>=1,"Finished",IF(C23<=0,"Not started","In progress"))
A24: Không tính vào Progress — Unit test & Tối ưu hoá tương lai
A25: 21 | B25: Bộ test E2E | C25: 0.1 | D25: =IF(C25>=1,"Finished",IF(C25<=0,"Not started","In progress"))
B27: Tổng kết module (chỉ tính các feature phía trên) | C27: =AVERAGE(C4:C23) | D27: =COUNTIF(D4:D23,"Finished")&"/"&COUNTA(D4:D23)&" finished"
B29: Cách dùng: chỉ sửa cột C (Progress, 0%–100%). Cột D tự tính.
B30: Ô tô vàng = chưa hoàn thiện; di chuột vào tên feature để xem ghi chú kỹ thuật.
B31: Unit test và hạng mục tối ưu (nền xám) nằm ngoài vùng tổng kết, không ảnh hưởng Progress.

Sheet Database & Deployment
A1: Database & Deployment
A2: Nguồn: src/config + src/database + src/migrations
A3: No | B3: Feature Name | C3: Progress | D3: isDone
A4: 1 | B4: Factory cấu hình TypeORM bất đồng bộ | C4: 1 | D4: =IF(C4>=1,"Finished",IF(C4<=0,"Not started","In progress"))
A5: 2 | B5: Migration khởi tạo schema | C5: 1 | D5: =IF(C5>=1,"Finished",IF(C5<=0,"Not started","In progress"))
A6: 3 | B6: Script migration generate / run / revert | C6: 1 | D6: =IF(C6>=1,"Finished",IF(C6<=0,"Not started","In progress"))
A7: 4 | B7: Script seed dữ liệu nền | C7: 1 | D7: =IF(C7>=1,"Finished",IF(C7<=0,"Not started","In progress"))
A8: 5 | B8: Script seed dữ liệu ATS production | C8: 1 | D8: =IF(C8>=1,"Finished",IF(C8<=0,"Not started","In progress"))
A9: 6 | B9: Cột audit + xoá mềm trên entity cơ sở | C9: 1 | D9: =IF(C9>=1,"Finished",IF(C9<=0,"Not started","In progress"))
A10: 7 | B10: Dockerfile đóng gói ứng dụng | C10: 1 | D10: =IF(C10>=1,"Finished",IF(C10<=0,"Not started","In progress"))
A11: 8 | B11: Cấu hình kết nối Redis / BullMQ (Upstash + TLS) | C11: 1 | D11: =IF(C11>=1,"Finished",IF(C11<=0,"Not started","In progress"))
A12: 9 | B12: File .env.example mẫu cho môi trường mới | C12: 0 | D12: =IF(C12>=1,"Finished",IF(C12<=0,"Not started","In progress"))
B14: Tổng kết module (chỉ tính các feature phía trên) | C14: =AVERAGE(C4:C12) | D14: =COUNTIF(D4:D12,"Finished")&"/"&COUNTA(D4:D12)&" finished"
B16: Cách dùng: chỉ sửa cột C (Progress, 0%–100%). Cột D tự tính.
B17: Ô tô vàng = chưa hoàn thiện; di chuột vào tên feature để xem ghi chú kỹ thuật.
B18: Unit test và hạng mục tối ưu (nền xám) nằm ngoài vùng tổng kết, không ảnh hưởng Progress.
